//
//  Task+TimeoutTests.swift
//  FlyingFox
//
//  Created by Simon Whitty on 15/02/2022.
//  Copyright Â© 2022 Simon Whitty. All rights reserved.
//
//  Distributed under the permissive MIT license
//  Get the latest version from here:
//
//  https://github.com/swhitty/FlyingFox
//
//  Permission is hereby granted, free of charge, to any person obtaining a copy
//  of this software and associated documentation files (the "Software"), to deal
//  in the Software without restriction, including without limitation the rights
//  to use, copy, modify, merge, publish, distribute, sublicense, and/or sell
//  copies of the Software, and to permit persons to whom the Software is
//  furnished to do so, subject to the following conditions:
//
//  The above copyright notice and this permission notice shall be included in all
//  copies or substantial portions of the Software.
//
//  THE SOFTWARE IS PROVIDED "AS IS", WITHOUT WARRANTY OF ANY KIND, EXPRESS OR
//  IMPLIED, INCLUDING BUT NOT LIMITED TO THE WARRANTIES OF MERCHANTABILITY,
//  FITNESS FOR A PARTICULAR PURPOSE AND NONINFRINGEMENT. IN NO EVENT SHALL THE
//  AUTHORS OR COPYRIGHT HOLDERS BE LIABLE FOR ANY CLAIM, DAMAGES OR OTHER
//  LIABILITY, WHETHER IN AN ACTION OF CONTRACT, TORT OR OTHERWISE, ARISING FROM,
//  OUT OF OR IN CONNECTION WITH THE SOFTWARE OR THE USE OR OTHER DEALINGS IN THE
//  SOFTWARE.
//

@testable import FlyingSocks
import XCTest

final class TaskTimeoutTests: XCTestCase {

    func testTimeoutReturnsSuccess_WhenTimeoutDoesNotExpire() async throws {
        // given
        let value = try await Task(timeout: 0.5) {
            "Fish"
        }.value

        // then
        XCTAssertEqual(value, "Fish")
    }

    func testTimeoutThrowsError_WhenTimeoutExpires() async {
        // given
        let task = Task<Void, any Error>(timeout: 0.5) {
            try await Task.sleep(seconds: 10)
        }

        // then
        do {
            _ = try await task.value
            XCTFail("Expected SocketError.timeout")
        } catch {
            XCTAssertEqual(error as? SocketError, .makeTaskTimeout(seconds: 0.5))
        }
    }

    func testTimeoutCancels() async {
        // given
        let task = Task(timeout: 0.5) {
            try await Task.sleep(seconds: 10)
        }

        // when
        task.cancel()

        // then
        do {
            _ = try await task.value
            XCTFail("Expected CancellationError")
        } catch {
            XCTAssertTrue(error is CancellationError)
        }
    }

    func testTaskTimeoutParentThrowsError() async {
        let task = Task {
            try await Task.sleep(seconds: 10)
        }

        let parent = Task {
            try await task.getValue(cancelling: .whenParentIsCancelled)
        }

        parent.cancel()

        await AsyncAssertThrowsError(
            try await parent.value,
            of: CancellationError.self
        )
    }

    func testTaskTimeoutZeroThrowsError() async {
        let task = Task {
            try await Task.sleep(seconds: 10)
        }

        await AsyncAssertThrowsError(
            try await task.getValue(cancelling: .afterTimeout(seconds: 0)),
            of: CancellationError.self
        )
    }

    func testTaskTimeoutThrowsError() async {
        let task = Task {
            try await Task.sleep(seconds: 10)
        }

        // then
        do {
            try await task.getValue(cancelling: .afterTimeout(seconds: 0.1))
            XCTFail("Expected SocketError.timeout")
        } catch {
            XCTAssertEqual(error as? SocketError, .makeTaskTimeout(seconds: 0.1))
        }
    }

    func testTaskTimeoutParentReturnsSuccess() async {
        let task = Task { "Fish" }

        await AsyncAssertEqual(
            try await task.getValue(cancelling: .whenParentIsCancelled),
            "Fish"
        )
    }

    func testTaskTimeoutZeroReturnsSuccess() async {
        let task = Task { "Fish" }

        await AsyncAssertEqual(
            try await task.getValue(cancelling: .afterTimeout(seconds: 0)),
            "Fish"
        )
    }

    func testTaskTimeoutReturnsSuccess() async {
        let task = Task { "Fish" }

        await AsyncAssertEqual(
            try await task.getValue(cancelling: .afterTimeout(seconds: 0.1)),
            "Fish"
        )
    }

    @MainActor
    func testMainActor_ReturnsValue() async throws {
        let val = try await withThrowingTimeout(seconds: 1) {
            MainActor.assertIsolated()
            try await Task.sleep(nanoseconds: 1_000)
            MainActor.assertIsolated()
            return "Fish"
        }
        XCTAssertEqual(val, "Fish")
    }

    @MainActor
    func testMainActorThrowsError_WhenTimeoutExpires() async {
        do {
            try await withThrowingTimeout(seconds: 0.05) {
                MainActor.assertIsolated()
                defer { MainActor.assertIsolated() }
                try await Task.sleep(nanoseconds: 60_000_000_000)
            }
            XCTFail("Expected Error")
        } catch {
            XCTAssertEqual(error as? SocketError, .makeTaskTimeout(seconds: 0.05))
        }
    }

    func testSendable_ReturnsValue() async throws {
        let sendable = TestActor()
        let value = try await withThrowingTimeout(seconds: 1) {
            sendable
        }
        XCTAssertTrue(value === sendable)
    }

    func testNonSendable_ReturnsValue() async throws {
        let ns = try await withThrowingTimeout(seconds: 1) {
            NonSendable("chips")
        }
        XCTAssertEqual(ns.value, "chips")
    }

    func testActor_ReturnsValue() async throws {
        let val = try await TestActor("Fish").returningValue()
        XCTAssertEqual(val, "Fish")
    }

    func testActorThrowsError_WhenTimeoutExpires() async {
        do {
            _ = try await TestActor().returningValue(
                after: 60,
                timeout: 0.05
            )
            XCTFail("Expected Error")
        } catch {
            XCTAssertEqual(error as? SocketError, .makeTaskTimeout(seconds: 0.05))
        }
    }

    func testTimeout_Cancels() async {
        let task = Task {
            try await withThrowingTimeout(seconds: 1) {
                try await Task.sleep(nanoseconds: 1_000_000_000)
            }
        }

        task.cancel()

        do {
            _ = try await task.value
            XCTFail("Expected Error")
        } catch {
            XCTAssertTrue(error is CancellationError)
        }
    }
}

extension Task where Success: Sendable, Failure == any Error {

    // Start a new Task with a timeout.
    init(priority: TaskPriority? = nil, timeout: TimeInterval, operation: @escaping @Sendable () async throws -> Success) {
        self = Task(priority: priority) {
            try await withThrowingTimeout(seconds: timeout) {
                try await operation()
            }
        }
    }
}

extension Task where Success == Never, Failure == Never {
    static func sleep(seconds: TimeInterval) async throws {
        try await sleep(nanoseconds: UInt64(1_000_000_000 * seconds))
    }
}

public struct NonSendable<T> {
    public var value: T

    init(_ value: T) {
        self.value = value
    }
}

private final actor TestActor<T: Sendable> {

    private var value: T

    init(_ value: T) {
        self.value = value
    }

    init() where T == String {
        self.init("fish")
    }

    func returningValue(after sleep: TimeInterval = 0, timeout: TimeInterval = 1) async throws -> T {
        try await withThrowingTimeout(seconds: timeout) {
            try await Task.sleep(nanoseconds: UInt64(sleep * 1_000_000_000))
            self.assertIsolated()
            return self.value
        }
    }
}
